Workbook

Sheet Parámetros Sistema
A1: GESTIÓN DE JUBILACIONES - SISTEMA PREVISIONAL DEL JUEGO
A2: Archivo de control y simulación para el sistema de jubilaciones. Inputs en azul + fondo amarillo. Fórmulas en negro.
A4: 1. PARÁMETROS DEMOGRÁFICOS Y DE SISTEMA
A5: Parámetro | B5: Valor | C5: Unidad / Nota
A6: Edad legal de jubilación (hombres) | B6: 65 | C6: años
A7: Edad legal de jubilación (mujeres) | B7: 60 | C7: años
A8: Edad promedio efectiva de retiro | B8: 63 | C8: años
A9: Esperanza de vida al nacer | B9: 77.5 | C9: años
A10: Esperanza de vida a los 65 | B10: 18.2 | C10: años
A11: Tasa de fertilidad | B11: 1.8 | C11: hijos por mujer
A12: Crecimiento poblacional anual | B12: 0.008 | C12: %
A13: Población total (millones) | B13: 45 | C13: millones
A14: Población en edad de trabajar (15-64) | B14: 0.65 | C14: % de población
A15: Población >= edad jubilación | B15: 0.12 | C15: % de población
A16: Ratio de dependencia previsional | B16: 0.22 | C16: jubilados / activos
A18: 2. APORTES, BENEFICIOS Y FINANCIAMIENTO
A19: Parámetro | B19: Valor | C19: Unidad / Nota
A20: Tasa de aporte del trabajador | B20: 0.11 | C20: % del salario
A21: Tasa de aporte del empleador | B21: 0.16 | C21: % del salario
A22: Tasa total de aporte | B22: =B20+B21 -> 0.27 | C22: % (automático)
A23: Tasa de reemplazo promedio | B23: 0.65 | C23: % del último salario
A24: Jubilación mínima (en % del salario medio) | B24: 0.4 | C24: %
A25: Jubilación máxima (en % del salario medio) | B25: 1.5 | C25: %
A26: Índice de actualización de haberes | B26: 0.8 | C26: % de inflación + % de salarios
A27: Cobertura del sistema (% de ocupados) | B27: 0.72 | C27: %
A28: Porcentaje de morosidad / evasión | B28: 0.18 | C28: %
A29: Aporte del Estado (déficit estructural % PBI) | B29: 0.025 | C29: % del PBI
A31: 3. VARIABLES MACROECONÓMICAS VINCULADAS
A32: Parámetro | B32: Valor | C32: Unidad / Nota
A33: PBI nominal actual (millones moneda local) | B33: 650000 | C33: millones
A34: Crecimiento real del PBI esperado | B34: 0.025 | C34: % anual
A35: Inflación esperada anual | B35: 0.045 | C35: %
A36: Salario medio nominal anual | B36: 18500 | C36: moneda local
A37: Crecimiento real de salarios | B37: 0.015 | C37: %
A38: Tipo de cambio (moneda local / USD) | B38: 950 | C38: TC
A39: Gasto militar (% PBI) | B39: 0.018 | C39: % del PBI
A40: Déficit / Superávit fiscal total (% PBI) | B40: -0.015 | C40: % del PBI (negativo = déficit)
A42: NOTAS DE DISEÑO DEL JUEGO:
A43: • Los valores en azul + amarillo son INPUTS editables por el jugador o diseñador.
A44: • La tasa total de aporte (B22) es fórmula = aporte trabajador + empleador.
...

Sheet Proyección 10 años
A1: PROYECCIÓN FINANCIERA DEL SISTEMA PREVISIONAL (10 AÑOS)
A2: Basado en parámetros de la hoja 'Parámetros Sistema'. Todas las celdas de cálculo son fórmulas.
A4: Concepto | B4: 2026 | C4: 2027 | D4: 2028 | E4: 2029 | F4: 2030 | G4: 2031 | H4: 2032 | I4: 2033 | J4: 2034 | K4: 2035
A5: Población total (millones) | B5: ='Parámetros Sistema'!B13 -> 45 | C5: =B5*(1+'Parámetros Sistema'!B12) -> 45.36 | D5: =C5*(1+'Parámetros Sistema'!B12) -> 45.72288 | E5: =D5*(1+'Parámetros Sistema'!B12) -> 46.088663 | F5: =E5*(1+'Parámetros Sistema'!B12) -> 46.457372 | G5: =F5*(1+'Parámetros Sistema'!B12) -> 46.829031 | H5: =G5*(1+'Parámetros Sistema'!B12) -> 47.203664 | I5: =H5*(1+'Parámetros Sistema'!B12) -> 47.581293 | J5: =I5*(1+'Parámetros Sistema'!B12) -> 47.961943 | K5: =J5*(1+'Parámetros Sistema'!B12) -> 48.345639
A6: Población activa (millones) | B6: =B5*'Parámetros Sistema'!B14 -> 29.25 | C6: =B6*(1+'Parámetros Sistema'!B12*0.85) -> 29.4489 | D6: =C6*(1+'Parámetros Sistema'!B12*0.85) -> 29.649153 | E6: =D6*(1+'Parámetros Sistema'!B12*0.85) -> 29.850767 | F6: =E6*(1+'Parámetros Sistema'!B12*0.85) -> 30.053752 | G6: =F6*(1+'Parámetros Sistema'!B12*0.85) -> 30.258117 | H6: =G6*(1+'Parámetros Sistema'!B12*0.85) -> 30.463873 | I6: =H6*(1+'Parámetros Sistema'!B12*0.85) -> 30.671027 | J6: =I6*(1+'Parámetros Sistema'!B12*0.85) -> 30.87959 | K6: =J6*(1+'Parámetros Sistema'!B12*0.85) -> 31.089571
A7: Jubilados (millones) | B7: =B5*'Parámetros Sistema'!B15 -> 5.4 | C7: =B7*(1+'Parámetros Sistema'!B12*1.4) -> 5.46048 | D7: =C7*(1+'Parámetros Sistema'!B12*1.4) -> 5.5216374 | E7: =D7*(1+'Parámetros Sistema'!B12*1.4) -> 5.5834797 | F7: =E7*(1+'Parámetros Sistema'!B12*1.4) -> 5.6460147 | G7: =F7*(1+'Parámetros Sistema'!B12*1.4) -> 5.7092501 | H7: =G7*(1+'Parámetros Sistema'!B12*1.4) -> 5.7731937 | I7: =H7*(1+'Parámetros Sistema'!B12*1.4) -> 5.8378534 | J7: =I7*(1+'Parámetros Sistema'!B12*1.4) -> 5.9032374 | K7: =J7*(1+'Parámetros Sistema'!B12*1.4) -> 5.9693536
A8: Ratio de dependencia (jub/activos) | B8: =B7/B6 -> 0.18461538 | C8: =C7/C6 -> 0.18542221 | D8: =D7/D6 -> 0.18623255 | E8: =E7/E6 -> 0.18704644 | F8: =F7/F6 -> 0.18786389 | G8: =G7/G6 -> 0.18868491 | H8: =H7/H6 -> 0.18950951 | I8: =I7/I6 -> 0.19033772 | ... K8: =K7/K6 -> 0.19200502
A9: Masa salarial nominal (millones) | B9: =B6*'Parámetros Sistema'!B36*'Parámetros Sistema'!B27 -> 389610 | C9: =B9*(1+'Parámetros Sistema'!B34+'Parámetros Sistema'!B35+'Parámetros Sistema'!B12*0.85) -> 419532.05 | D9: =C9*(1+'Parámetros Sistema'!B34+'Parámetros Sistema'!B35+'Parámetros Sistema'!B12*0.85) -> 451752.11 | E9: =D9*(1+'Parámetros Sistema'!B34+'Parámetros Sistema'!B35+'Parámetros Sistema'!B12*0.85) -> 486446.67 | F9: =E9*(1+'Parámetros Sistema'!B34+'Parámetros Sistema'!B35+'Parámetros Sistema'!B12*0.85) -> 523805.78 | G9: =F9*(1+'Parámetros Sistema'!B34+'Parámetros Sistema'!B35+'Parámetros Sistema'!B12*0.85) -> 564034.06 | H9: =G9*(1+'Parámetros Sistema'!B34+'Parámetros Sistema'!B35+'Parámetros Sistema'!B12*0.85) -> 607351.87 | I9: =H9*(1+'Parámetros Sistema'!B34+'Parámetros Sistema'!B35+'Parámetros Sistema'!B12*0.85) -> 653996.5 | J9: =I9*(1+'Parámetros Sistema'!B34+'Parámetros Sistema'!B35+'Parámetros Sistema'!B12*0.85) -> 704223.43 | K9: =J9*(1+'Parámetros Sistema'!B34+'Parámetros Sistema'!B35+'Parámetros Sistema'!B12*0.85) -> 758307.79
A10: Recaudación previsional (millones) | B10: =B9*'Parámetros Sistema'!B22*(1-'Parámetros Sistema'!B28) -> 86259.654 | C10: =C9*'Parámetros Sistema'!B22*(1-'Parámetros Sistema'!B28) -> 92884.395 | D10: =D9*'Parámetros Sistema'!B22*(1-'Parámetros Sistema'!B28) -> 100017.92 | E10: =E9*'Parámetros Sistema'!B22*(1-'Parámetros Sistema'!B28) -> 107699.29 | F10: =F9*'Parámetros Sistema'!B22*(1-'Parámetros Sistema'!B28) -> 115970.6 | G10: =G9*'Parámetros Sistema'!B22*(1-'Parámetros Sistema'!B28) -> 124877.14 | H10: =H9*'Parámetros Sistema'!B22*(1-'Parámetros Sistema'!B28) -> 134467.71 | I10: =I9*'Parámetros Sistema'!B22*(1-'Parámetros Sistema'!B28) -> 144794.82 | J10: =J9*'Parámetros Sistema'!B22*(1-'Parámetros Sistema'!B28) -> 155915.07 | K10: =K9*'Parámetros Sistema'!B22*(1-'Parámetros Sistema'!B28) -> 167889.34
A11: Gasto en jubilaciones (millones) | B11: =B7*'Parámetros Sistema'!B36*'Parámetros Sistema'!B23 -> 64935 | C11: =B11*(1+'Parámetros Sistema'!B34+'Parámetros Sistema'!B35)*(C7/B7) -> 70258.631 | D11: =C11*(1+'Parámetros Sistema'!B34+'Parámetros Sistema'!B35)*(D7/B7) -> 76870.124 | E11: =D11*(1+'Parámetros Sistema'!B34+'Parámetros Sistema'!B35)*(E7/B7) -> 85045.736 | F11: =E11*(1+'Parámetros Sistema'!B34+'Parámetros Sistema'!B35)*(F7/B7) -> 95144.692 | G11: =F11*(1+'Parámetros Sistema'!B34+'Parámetros Sistema'!B35)*(G7/B7) -> 107635.03 | H11: =G11*(1+'Parámetros Sistema'!B34+'Parámetros Sistema'!B35)*(H7/B7) -> 123128.84 | I11: =H11*(1+'Parámetros Sistema'!B34+'Parámetros Sistema'!B35)*(I7/B7) -> 142430.5 | J11: =I11*(1+'Parámetros Sistema'!B34+'Parámetros Sistema'!B35)*(J7/B7) -> 166603.17 | K11: =J11*(1+'Parámetros Sistema'!B34+'Parámetros Sistema'!B35)*(K7/B7) -> 197060.96
A12: Resultado previsional (millones) | B12: =B10-B11 -> 21324.654 | C12: =C10-C11 -> 22625.764 | D12: =D10-D11 -> 23147.793 | E12: =E10-E11 -> 22653.557 | F12: =F10-F11 -> 20825.907 | G12: =G10-G11 -> 17242.108 | H12: =H10-H11 -> 11338.864 | I12: =I10-I11 -> 2364.3262 | ... K12: =K10-K11 -> -29171.612
A13: Resultado previsional (% PBI) | B13: =B12/'Parámetros Sistema'!B33 -> 0.03280716 | C13: =C12/('Parámetros Sistema'!B33*(1+'Parámetros Sistema'!B34)^1) -> 0.033959872 | D13: =D12/('Parámetros Sistema'!B33*(1+'Parámetros Sistema'!B34)^2) -> 0.033896004 | E13: =E12/('Parámetros Sistema'!B33*(1+'Parámetros Sistema'!B34)^3) -> 0.0323632 | F13: =F12/('Parámetros Sistema'!B33*(1+'Parámetros Sistema'!B34)^4) -> 0.029026529 | G13: =G12/('Parámetros Sistema'!B33*(1+'Parámetros Sistema'!B34)^5) -> 0.023445402 | H13: =H12/('Parámetros Sistema'!B33*(1+'Parámetros Sistema'!B34)^6) -> 0.015042257 | I13: =I12/('Parámetros Sistema'!B33*(1+'Parámetros Sistema'!B34)^7) -> 0.0030600391 | J13: =J12/('Parámetros Sistema'!B33*(1+'Parámetros Sistema'!B34)^8) -> -0.013495728 | K13: =K12/('Parámetros Sistema'!B33*(1+'Parámetros Sistema'!B34)^9) -> -0.035936211
A14: Aporte estatal necesario (% PBI) | B14: =IF(B13<0,-B13,0) -> 0 | C14: =IF(C13<0,-C13,0) -> 0 | D14: =IF(D13<0,-D13,0) -> 0 | E14: =IF(E13<0,-E13,0) -> 0 | F14: =IF(F13<0,-F13,0) -> 0 | G14: =IF(G13<0,-G13,0) -> 0 | H14: =IF(H13<0,-H13,0) -> 0 | I14: =IF(I13<0,-I13,0) -> 0 | ... K14: =IF(K13<0,-K13,0) -> 0.035936211
A15: Impacto en Déficit Fiscal total (% PBI) | B15: =B14+'Parámetros Sistema'!B29 -> 0.025 | C15: =C14+'Parámetros Sistema'!B29 -> 0.025 | D15: =D14+'Parámetros Sistema'!B29 -> 0.025 | E15: =E14+'Parámetros Sistema'!B29 -> 0.025 | F15: =F14+'Parámetros Sistema'!B29 -> 0.025 | G15: =G14+'Parámetros Sistema'!B29 -> 0.025 | H15: =H14+'Parámetros Sistema'!B29 -> 0.025 | I15: =I14+'Parámetros Sistema'!B29 -> 0.025 | J15: =J14+'Parámetros Sistema'!B29 -> 0.038495728 | K15: =K14+'Parámetros Sistema'!B29 -> 0.060936211
A17: Interpretación rápida:
A18: • Resultado previsional negativo = el sistema no se autofinancia → el Estado debe aportar → aumenta déficit → presión inflacionaria y deuda.
A19: • Ratio de dependencia creciente = envejecimiento → más presión futura.
A20: • Reformas (subir edad, bajar tasa de reemplazo, subir aportes) mejoran el resultado pero cuestan Capital Político.

Sheet Fórmulas Economía
A1: FÓRMULAS DE INFLACIÓN, TIPO DE CAMBIO Y VÍNCULOS CON JUBILACIONES
A3: 1. FÓRMULA DE INFLACIÓN (versión de juego)
A5: π_t = π_{t-1} × (1 - α) + β × EmisiónMonetaria_t + γ × BrechaProducto_t + δ × ShockCostos_t + ε × Expectativas_t + ζ × DéficitPrevisional_t
A7: Componentes:
A8: π_t | B8: Inflación del período actual
A9: π_{t-1} | B9: Inflación del período anterior (inercia)
A10: α | B10: Velocidad de anclaje de expectativas (0.3 – 0.6 recomendado)
A11: β | B11: Sensibilidad a la emisión monetaria (0.4 – 0.8)
A12: EmisiónMonetaria_t | B12: Proporcional al déficit fiscal monetizado (si no se financia con deuda real)
A13: γ | B13: Sensibilidad a la brecha de producto (demanda)
A14: BrechaProducto_t | B14: (PBI efectivo - PBI potencial) / PBI potencial
A15: δ | B15: Sensibilidad a shocks de costos (energía, alimentos, tipo de cambio)
A16: ε | B16: Peso de las expectativas (pueden ser adaptativas o racionales)
A17: ζ | B17: Impacto directo del déficit previsional sobre la emisión o el gasto
A19: Regla de juego importante (Superávit):
A20: Si DéficitFiscal_t ≤ 0 (superávit) → EmisiónMonetaria_t ≈ 0 → el término β desaparece → inflación tiende a caer hacia el ancla de expectativas.
A21: Además, el superávit permite acumular reservas o comprar oro → refuerza el tipo de cambio → reduce el componente δ (shock de costos importados).
A23: 2. FÓRMULA DE TIPO DE CAMBIO (versión de juego)
A25: e_t = e_{t-1} × [1 + (π_local - π_extranjero) + λ × (i_extranjero - i_local) + μ × FlujoCapitales_t + ν × ΔReservas_t + ξ × PrimaRiesgo_t]
A27: Componentes:
A28: e_t | B28: Tipo de cambio (moneda local por USD)
A29: (π_local - π_extranjero) | B29: Diferencial de inflación (PPP relativo)
A30: λ × (i* - i) | B30: Diferencial de tasas de interés (paridad descubierta)
A31: μ × FlujoCapitales | B31: Entrada/salida de capitales (inversión extranjera, carry trade)
A32: ν × ΔReservas | B32: Variación de reservas internacionales (incluye compra de oro)
A33: ξ × PrimaRiesgo | B33: Riesgo país, incertidumbre política, deuda/PBI alto
A35: Vínculo con Superávit y Oro:
A36: Cuando hay superávit fiscal el gobierno puede destinar parte del excedente a comprar oro o dólares → ΔReservas positivo → el tipo de cambio se aprecia o se estabiliza (ν > 0 reduce e_t).
A37: Esto baja la inflación importada y genera un círculo virtuoso: superávit → menos emisión → menos inflación → tipo de cambio más fuerte → menos inflación.
A39: 3. VÍNCULO JUBILACIONES → INFLACIÓN → TIPO DE CAMBIO
A40: Déficit previsional alto → aumenta el déficit fiscal total → si se monetiza → sube EmisiónMonetaria → sube π → se deprecia e → suben costos importados → más inflación (espiral).
A41: Por eso reformar el sistema previsional (aunque cueste Capital Político) es una de las herramientas más potentes para anclar inflación y estabilizar el tipo de cambio a mediano plazo.
A43: 4. RECAUDACIÓN TRIBUTARIA Y EFECTO DINÁMICO DEL CRECIMIENTO DE LA ECONOMÍA
A45: Recaudación estática (sin cambio de comportamiento):
A46: Recaudación_t = CargaTributaria × PBI_t
A48: Cuando cambia el tamaño de la economía (crecimiento o contracción):
A49: ΔRecaudación ≈ Elasticidad_Recaudación/PBI × ΔPBI × Recaudación_anterior
A50: Con Elasticidad (buoyancy) típica = 1.10 – 1.30. Si el PBI crece 3%, la recaudación tiende a crecer 3.3–3.9%.
... A66: Un superávit + deflación leve + baja de impuestos bien diseñada puede generar un círculo virtuoso: más actividad → más recaudación dinámica → superávit más fácil de mantener → más reservas pasivas.

Sheet Gasto Militar vs Previsional
A1: ANÁLISIS DE GASTO MILITAR EN EL PBI Y COMPARACIÓN CON GASTO PREVISIONAL
A3: 1. RANGOS REALISTAS DE GASTO MILITAR (% del PBI)
A4: Nivel | B4: % PBI típico | C4: Ejemplos | D4: Impacto en el juego
A5: Muy bajo | B5: 0.8% – 1.2% | C5: Japón (históricamente), Costa Rica, algunos europeos | D5: Baja disuasión, alto Capital Político interno, vulnerable a crisis
A6: Bajo-Medio | B6: 1.3% – 2.0% | C6: Mayoría de América Latina, Canadá, Alemania | D6: Equilibrio razonable para países sin amenazas inmediatas
A7: Medio | B7: 2.1% – 3.0% | C7: China, India, Reino Unido, Francia | D7: Capacidad de proyección regional, coste fiscal moderado
A8: Alto | B8: 3.1% – 4.5% | C8: EE.UU., Rusia, Corea del Sur, Israel | D8: Alta disuasión y proyección, presión fiscal y de oportunidad
A9: Muy alto | B9: > 4.5% | C9: Corea del Norte, algunos países en guerra | D9: Economía de guerra, alto coste político interno si no hay amenaza clara
A11: 2. TRADE-OFF GASTO MILITAR vs GASTO PREVISIONAL
A13: En el juego ambos compiten por el mismo presupuesto.
A14: • Subir gasto militar mejora Defensa, disuasión y Capital Diplomático (con aliados), pero aumenta déficit o reduce otros gastos.
A15: • El gasto previsional es rígido (derechos adquiridos) y tiene alto peso político: recortarlo cuesta mucho Capital Político.
A16: • Un país con alto gasto previsional + alto gasto militar suele tener déficit estructural → inflación y deuda crecientes.
A18: 3. REGLA DE DISEÑO RECOMENDADA
A19: Gasto Militar + Gasto Previsional + Intereses de la Deuda no deberían superar el 15-18% del PBI de forma sostenida sin generar problemas de sostenibilidad.
A20: Si el jugador quiere subir defensa de forma agresiva, debe:
A21: a) Tener superávit o espacio fiscal, o
A22: b) Reformar el sistema previsional (subir edad, bajar reemplazo), o
A23: c) Aceptar más déficit → más inflación y deterioro del tipo de cambio.
A25: 4. IMPACTO POLÍTICO DEL GASTO MILITAR
... A28: • Usar el gasto militar en operaciones exitosas (o especiales) puede generar gran Capital Político y Diplomático.

Sheet Reformas y Capital Político
A1: PARÁMETROS DETALLADOS DE REFORMA PREVISIONAL
A2: Sistema completo de reformas parametrizadas para el juego. Inputs en azul + amarillo. Efectos y costes políticos desglosados.
A4: 1. PARÁMETROS QUE SE PUEDEN REFORMAR
A5: Parámetro de Reforma | B5: Valor Actual | C5: Valor Propuesto | D5: Δ (cambio) | E5: Unidad | F5: Notas de implementación
A6: Edad legal jubilación hombres | B6: ='Parámetros Sistema'!B6 -> 65 | C6: 67 | D6: =C6-B6 -> 2 | E6: años | F6: Transición gradual recomendada (1 año cada 2 años calendario)
A7: Edad legal jubilación mujeres | B7: ='Parámetros Sistema'!B7 -> 60 | C7: 65 | D7: =C7-B7 -> 5 | E7: años | F7: Igualar géneros tiene coste político extra por grupos de género
A8: Edad efectiva promedio de retiro | B8: ='Parámetros Sistema'!B8 -> 63 | C8: 65 | D8: =C8-B8 -> 2 | E8: años | F8: Se mueve con incentivos y penalizaciones por retiro anticipado
A9: Años mínimos de aporte (jubilación plena) | B9: 30 | C9: 35 | D9: =C9-B9 -> 5 | E9: años | F9: Aumentar requisitos reduce gasto futuro; afecta a informales
A10: Tasa de aporte trabajador | B10: ='Parámetros Sistema'!B20 -> 0.11 | C10: 0.13 | D10: =C10-B10 -> 0.02 | E10: % salario | F10: Impacto directo en poder adquisitivo de los activos
A11: Tasa de aporte empleador | B11: ='Parámetros Sistema'!B21 -> 0.16 | C11: 0.18 | D11: =C11-B11 -> 0.02 | E11: % salario | F11: Impacto en costo laboral y competitividad empresarial
A12: Tasa de reemplazo promedio | B12: ='Parámetros Sistema'!B23 -> 0.65 | C12: 0.55 | D12: =C12-B12 -> -0.1 | E12: % último salario | F12: El parámetro más sensible políticamente
A13: Pensión mínima (% salario medio) | B13: ='Parámetros Sistema'!B24 -> 0.4 | C13: 0.35 | D13: =C13-B13 -> -0.05 | E13: % | F13: Bajarla afecta a los más pobres → alto riesgo social
A14: Pensión máxima (% salario medio) | B14: ='Parámetros Sistema'!B25 -> 1.5 | C14: 1.2 | D14: =C14-B14 -> -0.3 | E14: % | F14: Bajar techos es más fácil políticamente (afecta altos ingresos)
A15: Índice de actualización de haberes | B15: ='Parámetros Sistema'!B26 -> 0.8 | C15: 0.7 | D15: =C15-B15 -> -0.1 | E15: % (infl+salarios) | F15: 0.5 = solo inflación; 1.0 = inflación + salarios reales
A16: Edad acceso a pensión mínima | B16: 65 | C16: 67 | D16: =C16-B16 -> 2 | E16: años | F16: Puede ser distinta a la edad de jubilación plena
A17: Morosidad / evasión objetivo | B17: ='Parámetros Sistema'!B28 -> 0.18 | C17: 0.12 | D17: =C17-B17 -> -0.06 | E17: % | F17: Requiere capacidad de fiscalización (ministros competentes)
A18: Cobertura del sistema (objetivo) | B18: ='Parámetros Sistema'!B27 -> 0.72 | C18: 0.8 | D18: =C18-B18 -> 0.08 | E18: % ocupados | F18: Formalización: lenta pero genera Capital Político positivo
A21: 2. COSTE EN CAPITAL POLÍTICO POR REFORMA (desglosado por grupo afectado)
A22: Coste total = suma de impactos por grupo. Moduladores: crisis fiscal, inflación alta, Capital Político previo alto y transición gradual reducen el coste.
A23: Reforma | B23: Activos | C23: Jubilados | D23: Empresas | E23: Género | F23: Privilegios | G23: Coste base | H23: Moduladores clave
A24: Subir edad jubilación hombres +2 | B24: -3 | C24: -1 | D24: 0 | E24: 0 | F24: 0 | G24: -4 | H24: Crisis fiscal reduce 30-40%
A25: Subir edad jubilación mujeres +5 | B25: -2 | C25: -2 | D25: 0 | E25: -4 | F25: 0 | G25: -8 | H25: Muy sensible; requiere compensación
A26: Igualar edad hombres/mujeres | B26: -1 | C26: -1 | D26: 0 | E26: -5 | F26: 0 | G26: -7 | H26: Costo de género alto corto plazo
A27: Subir años de aporte +5 | B27: -4 | C27: 0 | D27: 0 | E27: -1 | F27: 0 | G27: -5 | H27: Afecta carreras interrumpidas
A28: Subir aporte trabajador +2pp | B28: -5 | C28: 0 | D28: 0 | E28: -1 | F28: 0 | G28: -6 | H28: Impacto inmediato en bolsillo
A29: Subir aporte empleador +2pp | B29: -1 | C29: 0 | D29: -4 | E29: 0 | F29: 0 | G29: -5 | H29: Empresas presionan; menos inversión
A30: Bajar tasa reemplazo -10pp | B30: -2 | C30: -6 | D30: 0 | E30: -1 | F30: -2 | G30: -11 | H30: Jubilados futuros se enojan mucho
A31: Bajar pensión máxima (techos) | B31: 0 | C31: -2 | D31: 0 | E31: 0 | F31: -3 | G31: -5 | H31: Más fácil: afecta altos ingresos
A32: Bajar pensión mínima | B32: -1 | C32: -5 | D32: 0 | E32: -2 | F32: 0 | G32: -8 | H32: Muy peligroso socialmente
A33: Reducir índice de actualización | B33: 0 | C33: -4 | D33: 0 | E33: -1 | F33: -1 | G33: -6 | H33: Pérdida de poder adquisitivo
A34: Eliminar jubilaciones de privilegio | B34: 2 | C34: -1 | D34: 0 | E34: 0 | F34: -8 | G34: -7 | H34: Popular en población; odio en afectados
A35: Aumentar cobertura / formalización | B35: 3 | C35: 1 | D35: -2 | E35: 1 | F35: 0 | G35: 3 | H35: Única reforma con Capital neto positivo
A36: Introducir capitalización parcial | B36: -3 | C36: -2 | D36: 1 | E36: -1 | F36: -2 | G36: -7 | H36: Transición de 20-40 años
A39: 3. EFECTOS FISCALES ESTIMADOS POR REFORMA (orden de magnitud % PBI)
A40: Reforma | B40: Año 1-2 | C40: Año 5 | D40: Año 10 | E40: Velocidad impacto | F40: Dificultad técnica
A41: Subir edad +2 años (ambos sexos) | B41: 0.0015 | C41: 0.006 | D41: 0.012 | E41: Media-Lenta | F41: Media
A42: Subir edad +5 años | B42: 0.0025 | C42: 0.011 | D42: 0.028 | E42: Lenta | F42: Media
A43: Subir años de aporte +5 | B43: 0.001 | C43: 0.0045 | D43: 0.009 | E43: Media | F43: Baja
A44: Subir aportes totales +4pp | B44: 0.008 | C44: 0.009 | D44: 0.01 | E44: Inmediata | F44: Baja
A45: Bajar tasa reemplazo -10pp | B45: 0.002 | C45: 0.007 | D45: 0.014 | E45: Media | F45: Media
...

Sheet Dashboard Rápido
A1: DASHBOARD DE SOSTENIBILIDAD PREVISIONAL Y FISCAL
A3: Indicadores clave (se actualizan al cambiar parámetros)
A5: Indicador | B5: Valor actual | C5: Umbral de alerta | D5: Estado
A6: Ratio de dependencia | B6: ='Parámetros Sistema'!B16 -> 0.22 | C6: > 0.30 | D6: Observar
A7: Tasa total de aporte | B7: ='Parámetros Sistema'!B22 -> 0.27 | C7: > 0.35 o < 0.20 | D7: OK
A8: Tasa de reemplazo | B8: ='Parámetros Sistema'!B23 -> 0.65 | C8: > 0.80 | D8: Observar
A9: Aporte estatal estructural (% PBI) | B9: ='Parámetros Sistema'!B29 -> 0.025 | C9: > 0.03 | D9: Alerta si alto
A10: Gasto militar (% PBI) | B10: ='Parámetros Sistema'!B39 -> 0.018 | C10: > 0.03 | D10: Según amenaza
A11: Déficit/Superávit fiscal (% PBI) | B11: ='Parámetros Sistema'!B40 -> -0.015 | C11: < -0.03 | D11: Crítico si déficit grande
A13: CÓMO USAR ESTE ARCHIVO EN EL JUEGO
A14: 1. El diseñador o el jugador modifica los inputs amarillos en 'Parámetros Sistema'.
A15: 2. La hoja 'Proyección 10 años' muestra la evolución automática del déficit previsional.
A16: 3. 'Fórmulas Economía' explica cómo el déficit previsional alimenta inflación y tipo de cambio.
A17: 4. 'Gasto Militar vs Previsional' ayuda a balancear las dos grandes rigideces del presupuesto.
A18: 5. 'Reformas y Capital Político' da el menú de opciones costosas pero necesarias.
A19: 6. El Dashboard resume el estado de salud del sistema.

Sheet Calculadora Reforma
A1: CALCULADORA DE IMPACTO DE UNA REFORMA PREVISIONAL
A2: Modifica los valores amarillos. La calculadora estima efecto fiscal a 10 años y coste político (base y final con moduladores).
A4: PARÁMETROS DE LA REFORMA A SIMULAR
A5: Variable | B5: Valor base | C5: Nuevo valor | D5: Cambio (Δ) | E5: Peso relativo
A6: Δ Edad jubilación promedio (años) | B6: 0 | C6: 2 | D6: =C6-B6 -> 2 | E6: 0.35
A7: Δ Tasa aporte total (pp decimales) | B7: 0 | C7: 0.02 | D7: =C7-B7 -> 0.02 | E7: 0.25
A8: Δ Tasa de reemplazo (pp decimales) | B8: 0 | C8: -0.05 | D8: =C8-B8 -> -0.05 | E8: 0.3
A9: Δ Índice actualización (pp) | B9: 0 | C9: -0.1 | D9: =C9-B9 -> -0.1 | E9: 0.15
A10: Δ Cobertura formalización (pp) | B10: 0 | C10: 0.05 | D10: =C10-B10 -> 0.05 | E10: 0.2
A11: Eliminación privilegios (0=no / 1=sí) | B11: 0 | C11: 0 | D11: =C11-B11 -> 0 | E11: 0.1
A13: RESULTADOS ESTIMADOS
A14: Efecto fiscal estimado a 10 años (% PBI) | B14: =D6*0.006 + D7*0.45 + D8*(-0.28) + D9*(-0.12) + D10*0.14 + D11*0.007 -> 0.054
A15: Coste Capital Político estimado (base) | B15: =D6*(-2) + D7*(-250) + D8*120 + D9*50 + D10*(-20) + D11*(-7) -> -21
A16: Riesgo de protestas (escala 0-10) | B16: =MIN(10,ABS(B15)*0.55) -> 10
A18: MODULADORES DE COSTE POLÍTICO
A19: ¿Hay crisis fiscal visible? (1=sí / 0=no) | B19: 0
A20: ¿Inflación anual > 8%? (1=sí / 0=no) | B20: 0
A21: Capital Político actual del gobierno | B21: 10
A22: ¿Transición gradual? (1=sí / 0=no) | B22: 1
A24: COSTE POLÍTICO FINAL (después de moduladores) | B24: =B15*(1-0.35*B19)*(1-0.2*B20)*(1-0.15*IF(B21>=15,1,0))*(1-0.25*B22) -> -15.75
A26: Interpretación del coste final:
A27: 0 a -3 → Reforma relativamente barata políticamente
A28: -3 a -7 → Coste significativo, requiere Capital Político sólido
A29: -7 a -12 → Reforma dura, solo viable con crisis o gran capital
A30: < -12 → Paquete de shock, alto riesgo de crisis política
A32: NOTA: Fórmulas de orden de magnitud para diseño del juego. El efecto real depende del punto de partida demográfico y de la velocidad de transición.
A36: CALCULADORA RÁPIDA DE EFECTO DINÁMICO DE BAJA DE IMPUESTOS
A38: Parámetros de simulación (editar amarillos)
A39: Carga tributaria actual (% PBI) | B39: 0.28
A40: Reducción de carga tributaria (pp) | B40: 0.02
A41: Elasticidad PBI / carga tributaria | B41: -0.35
A42: Elasticidad recaudación / PBI | B42: 1.15
A43: Recaudación actual (base 100) | B43: 100
A45: RESULTADOS
A46: Pérdida estática de recaudación (%) | B46: =B40/B39 -> 0.071428571
A47: ΔPBI estimado por la baja de impuestos | B47: =-B40*B41 -> 0.007
A48: Recuperación dinámica de recaudación vía crecimiento (%) | B48: =B47*B42 -> 0.00805
A49: Efecto neto estimado a mediano plazo (% recaudación) | B49: =-B46+B48 -> -0.063378571
A51: Interpretación: si el efecto neto es cercano a 0 o positivo, la baja de impuestos se autopaga (o casi) a mediano plazo vía mayor actividad económica.
A52: Nota: esta calculadora es simplificada (no incluye formalización ni lags). El efecto real depende del contexto macro y de la credibilidad de la baja.

Sheet Impacto en Empleo
A1: ANÁLISIS DEL IMPACTO EN EL EMPLEO
A2: Cómo las decisiones fiscales, previsionales y de reforma afectan el empleo formal, informal, desempleo y la participación laboral en el juego.
A4: 1. PRINCIPALES CANALES DE IMPACTO SOBRE EL EMPLEO
A5: Canal | B5: Dirección del efecto | C5: Magnitud típica | D5: Velocidad | E5: Grupo más afectado | F5: Notas de diseño
A6: Subir tasa de aporte trabajador | B6: ↓ Empleo formal / ↑ Informalidad | C6: Media-Alta | D6: Rápida | E6: Trabajadores de baja calificación | F6: Reduce poder adquisitivo y formalidad
A7: Subir tasa de aporte empleador | B7: ↓ Contratación formal / ↑ Informalidad | C7: Alta | D7: Rápida | E7: PyMEs y sectores intensivos en mano de obra | F7: Aumenta costo laboral no salarial
A8: Subir edad de jubilación | B8: ↑ Participación laboral (PEA) | C8: Media | D8: Lenta (años) | E8: Trabajadores 60-65 | F8: Más gente activa → más oferta laboral
A9: Bajar tasa de reemplazo | B9: ↑ Oferta laboral (gente posterga retiro) | C9: Baja-Media | D9: Media | E9: Próximos a jubilarse | F9: Incentivo a seguir trabajando
A10: Formalización / ↑ cobertura | B10: ↑ Empleo formal / ↓ Informalidad | C10: Media | D10: Lenta | E10: Informales y autónomos | F10: Requiere capacidad de fiscalización
A11: Crecimiento del PBI | B11: ↑ Empleo total (elasticidad ~0.5) | C11: Alta | D11: Media | E11: Todos los sectores | F11: Principal driver de creación de empleo
A12: Inflación alta | B12: ↓ Empleo real / ↑ Informalidad | C12: Media | D12: Rápida | E12: Asalariados formales | F12: Erosión de salarios reales
A13: Gasto militar alto | B13: ↑ Empleo defensa / ↓ otros sectores | C13: Baja-Media | D13: Media | E13: Sector público y proveedores | F13: Oportunidad de coste fiscal
A14: Superávit fiscal sostenido | B14: ↑ Confianza → ↑ Inversión → ↑ Empleo | C14: Media | D14: Lenta | E14: Sector privado | F14: Efecto indirecto positivo
A15: Déficit alto + deuda creciente | B15: ↓ Inversión privada → ↓ Empleo | C15: Media-Alta | D15: Media | E15: Sector privado | F15: Crowding-out y riesgo país
A18: 2. FÓRMULAS SIMPLIFICADAS DE IMPACTO EN EMPLEO (versión de juego)
A20: Cambio en Empleo Formal (%) ≈
A21: ε × ΔPBI − α × Δ(Tasa Aporte Total) − β × Δ(Costo Laboral) + γ × ΔCobertura + δ × Δ(Edad Jubilación efectiva)
A23: Donde:
A24: ε (elasticidad empleo-PBI) ≈ 0.4 – 0.6 | α ≈ 0.8 – 1.5 | β ≈ 0.6 – 1.2 | γ ≈ 0.3 – 0.7 | δ ≈ 0.1 – 0.25 por año de edad
A26: Cambio en Tasa de Desempleo ≈ − (Cambio en Empleo Formal + Cambio en Informalidad neta) / PEA
A28: Cambio en Informalidad ≈ −ΔCobertura + θ × Δ(Aportes) + efectos de crecimiento y regulación
A30: 3. TRADE-OFFS CLAVE PARA EL JUGADOR
A31: • Subir aportes mejora la caja previsional YA, pero destruye empleo formal y puede aumentar la informalidad → menos recaudación futura y más presión social.
A32: • Formalizar el empleo es win-win a largo plazo (más aportes + más Capital Político), pero requiere ministro de Trabajo/Economía competente y tiempo.
A33: • Subir la edad de jubilación aumenta la oferta laboral (más gente activa) y mejora el sistema previsional, pero genera rechazo en los afectados.
A34: • Un paquete de reforma previsional agresivo puede bajar el desempleo estructural a mediano plazo si se combina con crecimiento, pero en el corto plazo puede subir el desempleo si destruye formalidad.
... A40: El desempleo y la informalidad son de los drivers más fuertes del voto y del Capital Político:
A41: Evento | B41: Impacto en Capital Político | C41: Intensidad percibida
A42: Suba de 1 pp en desempleo abierto | B42: −1.5 a −3.0 Capital Político | C42: Muy alto rechazo
A43: Baja de 1 pp en desempleo | B43: +1.0 a +2.0 Capital Político | C43: Fuerte premio político
A44: Suba de informalidad visible | B44: −0.5 a −1.5 (menos que desempleo) | C44: Enojo moderado
A45: Creación de empleo formal neto | B45: +1.0 a +2.5 según magnitud | C45: Uno de los mejores generadores de capital
A46: Destrucción de empleo formal por reforma | B46: −2.0 a −5.0 según tamaño | C46: Puede tumbar gobiernos
A48: 5. RECOMENDACIÓN DE DISEÑO
A49: El empleo no debe ser un indicador secundario. Debe ser uno de los 3-4 indicadores que más mueven la aprobación ciudadana (junto con inflación, poder adquisitivo y seguridad).
A50: Las reformas previsionales deben mostrar claramente el trade-off: mejor sostenibilidad fiscal vs riesgo de destrucción de empleo formal en el corto plazo.
A51: Un buen ministro de Trabajo o Economía puede mitigar parte del daño de subas de aportes (mejor fiscalización + incentivos a la formalización).
A53: 6. IMPACTO EN SALARIOS (vinculado a empleo y previsional)
A54: Factor | B54: Efecto en salarios reales | C54: Efecto en salarios nominales | D54: Velocidad | E54: Notas
A55: Suba de aportes del trabajador | B55: ↓ Fuerte (neto) | C55: Neutro o leve ↓ | D55: Inmediata | E55: El trabajador siente la pérdida neta de inmediato
...
